Exception in thread Thread-31:
Traceback (most recent call last):
  File "/home/ubuntu/miniconda2/lib/python2.7/threading.py", line 801, in __bootstrap_inner
    self.run()
  File "/home/ubuntu/miniconda2/lib/python2.7/threading.py", line 754, in run
    self.__target(*self.__args, **self.__kwargs)
  File "/home/ubuntu/miniconda2/lib/python2.7/site-packages/keras/engine/training.py", line 433, in data_generator_task
    generator_output = next(generator)
  File "/home/ubuntu/miniconda2/lib/python2.7/site-packages/keras/preprocessing/image.py", line 605, in next
    x = self.image_data_generator.random_transform(x)
  File "/home/ubuntu/miniconda2/lib/python2.7/site-packages/keras/preprocessing/image.py", line 362, in random_transform
    fill_mode=self.fill_mode, cval=self.cval)
  File "/home/ubuntu/miniconda2/lib/python2.7/site-packages/keras/preprocessing/image.py", line 108, in apply_transform
    final_offset, order=0, mode=fill_mode, cval=cval) for x_channel in x]
AttributeError: 'NoneType' object has no attribute 'interpolation'

